Workbook

Sheet README
A1: kulcs | B1: ertek
A2: dokumentum_cel | B2: Az Energofish nagyker termékfeed (termekadatok_hu.xml) pontos szerkezeti specifikációja feldolgozó kód (pl. Claude Code) számára: mi hol van az XML-ben, hogyan kell értelmezni, mivé kell alakítani, és hogyan kell ellenőrizni.
A3: forras_url | B3: https://energofish.hu/listak/feeds/wholesale/termekadatok_hu.xml
A4: elemzett_allapot | B4: 2026-10-02-i letöltés; minden darabszám és statisztika erre a teljes fájlra vonatkozik
A5: fajlmeret_bajt | B5: 48515178
A6: kodolas | B6: UTF-8, deklaráció: <?xml version="1.0" encoding="utf-8"?>
A7: gyokerelem | B7: /xml (az elem neve szó szerint "xml")
A8: rekord_elem | B8: /xml/Termek – egy rekord = egy cikk (variáns)
A9: termek_db | B9: 12433
A10: fotermek_db | B10: 3623
A11: rekord_kulcs | B11: Cikkszam (egyedi, nincs duplikátum). Szövegként kezelendő: betűt, "/" és "_" jelet is tartalmazhat (pl. MA4011/0, SBSLAS_G).
A12: sema_stabilitas | B12: Mind a 12 433 Termek pontosan ugyanazt a 37 gyerekelemet tartalmazza, azonos sorrendben. Skalár elem soha nem hiányzik, legfeljebb üres. Csak a Kep, Parameter és Jellemzo ismétlődő elemek száma változik.
A13: ures_ertek_formak | B13: <X></X> vagy <X><![CDATA[]]></X> (önlezáró tag nincs). Video üresen: <Video title=""></Video>. Feldolgozáskor: strip után üres string → NULL.
A14: cdata_mezok | B14: Termeknev, Fotermek, Kategoria, Alkategoria, Marka_gyarto, Termekleiras, Parameter, Jellemzo, Video (csak ha kitöltött). A többi elem sima szöveg.
A15: xml_entitasok | B15: A nem-CDATA szövegekben (pl. URL-ek) entitások lehetnek (&amp;). Szabványos XML parsert kell használni, regexes/szöveges feldolgozás nem megbízható.
A16: whitespace_szabaly | B16: Minden szöveges értéket strip-elni kell, a nem törő szóközt (U+00A0) is beleértve (pl. "Feeder " alkategória, NBSP egy vonalkód elején). 1 011 termék érintett.
A17: szam_formatum | B17: Egész számok ezres elválasztó nélkül. Tizedes: pont, mindig 4 tizedes (KartonSuly, KartonTerfogat). Árak egész Ft.
A18: datum_formatum | B18: Letrehozas_datuma: "YYYY-MM-DD HH:MM:SS" (helyi idő, időzóna nincs megadva). "0000-00-00 00:00:00" → NULL.
A19: penznem_es_afa | B19: Minden ár HUF. Nagyker_* = nettó, Kisker_* = bruttó (27% ÁFA). Akciós ár 0 = nincs akció.
A20: feldolgozasi_javaslat | B20: Streaming parser (xml.etree.ElementTree.iterparse vagy lxml.etree.iterparse) a Termek "end" eseményén, utána elem.clear(). A teljes fájl memóriába töltése is működik (~48 MB), de felesleges.
A21: kimeneti_modell | B21: 4 fő tábla: termek, termek_kep, termek_parameter, termek_jellemzo (kulcs: cikkszam) + 3 opcionális származtatott dimenzió: fotermek, kategoria, alkategoria. Részletek: cel_adatmodell.
A22: ures_gyerekelem_szabaly | B22: Üres értékű Kep / Parameter / Jellemzo elemből NEM keletkezik sor a gyerektáblákban. A teljes feedre ez 68 166 kép-, 54 597 paraméter- és 2 668 jellemzősort jelent.
... A36: lap: minta_jellemzo | B36: ELVÁRT KIMENET: a termek_jellemzo tábla a 10729-300 rekordra (az első 10-ben nincs Jellemzo).

Sheet xml_szerkezet
A1: xpath | B1: relativ_xpath | C1: szulo_xpath | D1: node_tipus | E1: szint | F1: sorrend_szulon_belul | G1: kardinalitas | H1: ismetlodo_kulcs | I1: cdata | J1: ertek_tipus | K1: formatum_regex | L1: regex_illeszkedik (db / nem üres) | M1: ures_lehet | N1: ures_jelentese | O1: db_egysege | P1: elofordul_db | Q1: nem_ures_db | R1: kitoltottseg | S1: distinct_db | T1: min_ertek | U1: max_ertek | V1: max_hossz | W1: pelda_ertek | X1: cel_tabla | Y1: cel_oszlop | Z1: leiras | AA1: megjegyzes | AB1: statusz
A2: /xml | B2: /xml | D2: element (gyökér) | E2: 0 | F2: 1 | G2: 1..1 | I2: nem | J2: konténer | M2: nem | P2: 1 | R2: =IF(OR(P2="",Q2="",P2=0),"",Q2/P2) | Z2: Gyökérelem; csak Termek gyerekei vannak. | AB2: megerositett
A3: /xml/Termek | B3: . | C3: /xml | D3: element (rekord) | E3: 1 | F3: 1 | G3: 1..n | I3: nem | J3: konténer | M3: nem | O3: termek | P3: 12433 | R3: =IF(OR(P3="",Q3="",P3=0),"",Q3/P3) | S3: 12433 | X3: termek | Y3: (1 sor / Termek) | Z3: Egy cikk (variáns). 37 gyerekelem fix sorrendben. | AB3: megerositett
A4: /xml/Termek/Cikkszam | B4: Cikkszam | C4: /xml/Termek | D4: element | E4: 2 | F4: 1 | G4: 1..1 | I4: nem | J4: string | K4: ^[0-9A-Z/_]{8}$ | L4: 12433 / 12433 | M4: nem | O4: termek | P4: 12433 | Q4: 12433 | R4: =IF(OR(P4="",Q4="",P4=0),"",Q4/P4) -> 1 | S4: 12433 | V4: 8 | W4: 10000327 | X4: termek | Y4: cikkszam | Z4: Cikkszám kötőjel nélkül; elsődleges kulcs. | AA4: Értéke a CikkszamK kötőjel nélkül (V02). | AB4: megerositett
A5: /xml/Termek/CikkszamK | B5: CikkszamK | C5: /xml/Termek | D5: element | E5: 2 | F5: 2 | G5: 1..1 | I5: nem | J5: string | K5: ^[0-9A-Z]{5}-[0-9A-Z/_]{3}$ | L5: 12433 / 12433 | M5: nem | O5: termek | P5: 12433 | Q5: 12433 | R5: =IF(OR(P5="",Q5="",P5=0),"",Q5/P5) -> 1 | S5: 12433 | V5: 9 | W5: 10000-327 | X5: termek | Y5: cikkszam_k | Z5: Cikkszám kötőjeles formában ("ccccc-vvv"). | AA5: Parameter[@id=5] ugyanezt ismétli (V03). | AB5: megerositett
A6: /xml/Termek/Termeknev | B6: Termeknev | C6: /xml/Termek | D6: element | E6: 2 | F6: 3 | G6: 1..1 | I6: igen | J6: string | M6: nem | O6: termek | P6: 12433 | Q6: 12433 | R6: =IF(OR(P6="",Q6="",P6=0),"",Q6/P6) -> 1 | S6: 12390 | V6: 94 | W6: CRAB RED 12CM | X6: termek | Y6: termeknev | Z6: A variáns neve. | AA6: Tartalmazhat &, angol rövidítéseket (pl. 10PCS/BAG). | AB6: megerositett
A7: /xml/Termek/Fotermek | B7: Fotermek | C7: /xml/Termek | D7: element | E7: 2 | F7: 4 | G7: 1..1 | I7: igen | J7: string | M7: nem | O7: termek | P7: 12433 | Q7: 12433 | R7: =IF(OR(P7="",Q7="",P7=0),"",Q7/P7) -> 1 | S7: 3605 | V7: 96 | W7: WIZARD CRAB | X7: termek | Y7: fotermek_nev | Z7: Főtermék (termékcsalád) neve. | AA7: A név nem egyedi: 3 605 név 3 623 id-hoz. | AB7: megerositett
A8: /xml/Termek/Fotermek/@id | B8: Fotermek/@id | C8: /xml/Termek/Fotermek | D8: attribute | E8: 3 | F8: attr | G8: 1..1 | I8: nem | J8: integer | K8: ^\d+$ | L8: 12433 / 12433 | M8: nem | O8: termek | P8: 12433 | Q8: 12433 | R8: =IF(OR(P8="",Q8="",P8=0),"",Q8/P8) -> 1 | S8: 3623 | T8: 80 | U8: 26255 | W8: 24021 | X8: termek | Y8: fotermek_id | Z8: Főtermék azonosító; a variánsokat fogja össze (átlag 3,4, max 61 variáns). | AB8: megerositett
A9: /xml/Termek/Termek_link | B9: Termek_link | C9: /xml/Termek | D9: element | E9: 2 | F9: 5 | G9: 1..1 | I9: nem | J9: url | K9: ^https://energofish\.hu/product\.php/[^/]+/\d+/$ | L9: 12433 / 12433 | M9: nem | O9: termek | P9: 12433 | Q9: 12433 | R9: =IF(OR(P9="",Q9="",P9=0),"",Q9/P9) -> 1 | S9: 3624 | V9: 146 | W9: https://energofish.hu/product.php/Mucsali-WIZARD-CRAB/24021/ | X9: termek | Y9: termek_link | Z9: A főtermék webshop oldala (az URL végén a Fotermek @id). | AA9: Főtermékenként azonos, 1 kivétellel (18489, V25). | AB9: megerositett
A10: /xml/Termek/Vonalkod | B10: Vonalkod | C10: /xml/Termek | D10: element | E10: 2 | F10: 6 | G10: 1..1 | I10: nem | J10: string (EAN-13) | K10: ^\d{13}$ | L10: 12292 / 12322 | M10: igen | N10: nincs vonalkód | O10: termek | P10: 12433 | Q10: 12322 | R10: =IF(OR(P10="",Q10="",P10=0),"",Q10/P10) -> 0.99107215 | S10: 12323 | V10: 13 | W10: 5999018248267 | X10: termek | Y10: vonalkod | Z10: Elsődleges vonalkód. | AA10: Szövegként tárolandó! 30 db nem 13 jegyű, 9 db hibás ellenőrző számjegy (V06–V08). | AB10: megerositett
A11: /xml/Termek/Vonalkod2 | B11: Vonalkod2 | C11: /xml/Termek | D11: element | E11: 2 | F11: 7 | G11: 1..1 | I11: nem | J11: string (EAN/GTIN) | K11: ^\d{12,14}$ | L11: 1816 / 1822 | M11: igen | N11: nincs második vonalkód | O11: termek | P11: 12433 | Q11: 1822 | R11: =IF(OR(P11="",Q11="",P11=0),"",Q11/P11) -> 0.14654548 | S11: 1823 | V11: 14 | W11: 5999065638578 | X11: termek | Y11: vonalkod2 | Z11: Második vonalkód. | AA11: 12–14 jegyű; 5 db sérült (Excel tudományos alak, "ö" elütés), 1 db a cikkszám került ide (V09, V09b). | AB11: megerositett
A12: /xml/Termek/VTSZ_SZJ | B12: VTSZ_SZJ | C12: /xml/Termek | D12: element | E12: 2 | F12: 8 | G12: 1..1 | I12: nem | J12: string (8 számjegy) | K12: ^\d{8}$ | L12: 12420 / 12423 | M12: igen | N12: nincs VTSZ | O12: termek | P12: 12433 | Q12: 12423 | R12: =IF(OR(P12="",Q12="",P12=0),"",Q12/P12) -> 0.99919569 | S12: 119 | V12: 10 | W12: 95079000 | X12: termek | Y12: vtsz | Z12: Vámtarifaszám. | AA12: 2 db 10 jegyű, 1 db "..........". | AB12: megerositett
A13: /xml/Termek/Kategoria | B13: Kategoria | C13: /xml/Termek | D13: element | E13: 2 | F13: 9 | G13: 1..1 | I13: igen | J13: string | M13: igen | N13: id=1 esetén üres név | O13: termek | P13: 12433 | Q13: 12416 | R13: =IF(OR(P13="",Q13="",P13=0),"",Q13/P13) -> 0.99863267 | S13: 28 | V13: 22 | W13: Műcsali | X13: termek | Y13: kategoria_nev | Z13: Főkategória neve. | AA13: Lásd kategoriak lap. | AB13: megerositett
A14: /xml/Termek/Kategoria/@id | B14: Kategoria/@id | C14: /xml/Termek/Kategoria | D14: attribute | E14: 3 | F14: attr | G14: 1..1 | I14: nem | J14: integer | K14: ^\d+$ | L14: 12433 / 12433 | M14: nem | O14: termek | P14: 12433 | Q14: 12433 | R14: =IF(OR(P14="",Q14="",P14=0),"",Q14/P14) -> 1 | S14: 28 | T14: 1 | U14: 260 | W14: 210 | X14: termek | Y14: kategoria_id | Z14: Főkategória azonosító (28 féle). | AB14: megerositett
A15: /xml/Termek/Alkategoria | B15: Alkategoria | C15: /xml/Termek | D15: element | E15: 2 | F15: 10 | G15: 1..1 | I15: igen | J15: string | M15: nem | O15: termek | P15: 12433 | Q15: 12433 | R15: =IF(OR(P15="",Q15="",P15=0),"",Q15/P15) -> 1 | S15: 186 | V15: 26 | W15: Gumihal | X15: termek | Y15: alkategoria_nev | Z15: Alkategória neve. | AA15: 291 értéknél szóköz a végén ("Feeder ") → strip. | AB15: megerositett
A16: /xml/Termek/Alkategoria/@id | B16: Alkategoria/@id | C16: /xml/Termek/Alkategoria | D16: attribute | E16: 3 | F16: attr | G16: 1..1 | I16: nem | J16: integer | K16: ^\d+$ | L16: 12433 / 12433 | M16: nem | O16: termek | P16: 12433 | Q16: 12433 | R16: =IF(OR(P16="",Q16="",P16=0),"",Q16/P16) -> 1 | S16: 206 | T16: 999 | U16: 260030 | W16: 210040 | X16: termek | Y16: alkategoria_id | Z16: Alkategória azonosító; a Kategoria @id-val kezdődik (210 → 210040). | AA16: Kivétel: Kategoria 1 → Alkategoria 999 (V13). | AB16: megerositett
A17: /xml/Termek/Marka_gyarto | B17: Marka_gyarto | C17: /xml/Termek | D17: element | E17: 2 | F17: 11 | G17: 1..1 | I17: igen | J17: string | M17: nem | O17: termek | P17: 12433 | Q17: 12433 | R17: =IF(OR(P17="",Q17="",P17=0),"",Q17/P17) -> 1 | S17: 78 | V17: 19 | W17: Arno | X17: termek | Y17: marka | Z17: Márka / gyártó (78 féle). | AB17: megerositett
A18: /xml/Termek/Nagyker_netto | B18: Nagyker_netto | C18: /xml/Termek | D18: element | E18: 2 | F18: 12 | G18: 1..1 | I18: nem | J18: integer (HUF) | K18: ^\d+$ | L18: 12433 / 12433 | M18: nem | O18: termek | P18: 12433 | Q18: 12433 | R18: =IF(OR(P18="",Q18="",P18=0),"",Q18/P18) -> 1 | S18: 1097 | T18: 1 | U18: 6417180 | V18: 7 | W18: 395 | X18: termek | Y18: nagyker_netto_ft | Z18: Nagyker nettó listaár, Ft / értékesítési egység. | AB18: megerositett
A19: /xml/Termek/Nagyker_akcios_netto | B19: Nagyker_akcios_netto | C19: /xml/Termek | D19: element | E19: 2 | F19: 13 | G19: 1..1 | I19: nem | J19: integer (HUF) | K19: ^\d+$ | L19: 12433 / 12433 | M19: nem | N19: 0 = nincs akció (8 878 termék) | O19: termek | P19: 12433 | Q19: 12433 | R19: =IF(OR(P19="",Q19="",P19=0),"",Q19/P19) -> 1 | S19: 410 | T19: 0 | U19: 238190 | V19: 6 | W19: 320 | X19: termek | Y19: nagyker_akcios_netto_ft | Z19: Nagyker nettó akciós ár, Ft. | AA19: Akció jelzése: >0 (V14–V16). | AB19: megerositett
A20: /xml/Termek/Kisker_brutto | B20: Kisker_brutto | C20: /xml/Termek | D20: element | E20: 2 | F20: 14 | G20: 1..1 | I20: nem | J20: integer (HUF) | K20: ^\d+$ | L20: 12433 / 12433 | M20: nem | O20: termek | P20: 12433 | Q20: 12433 | R20: =IF(OR(P20="",Q20="",P20=0),"",Q20/P20) -> 1 | S20: 717 | T20: 10 | U20: 9055990 | V20: 7 | W20: 690 | X20: termek | Y20: kisker_brutto_ft | Z20: Kisker bruttó ár (27% ÁFA), Ft. | AB20: megerositett
A21: /xml/Termek/Kisker_akcios_brutto | B21: Kisker_akcios_brutto | C21: /xml/Termek | D21: element | E21: 2 | F21: 15 | G21: 1..1 | I21: nem | J21: integer (HUF) | K21: ^\d+$ | L21: 12433 / 12433 | M21: nem | N21: 0 = nincs akció | O21: termek | P21: 12433 | Q21: 12433 | R21: =IF(OR(P21="",Q21="",P21=0),"",Q21/P21) -> 1 | S21: 423 | T21: 0 | U21: 333890 | V21: 6 | W21: 530 | X21: termek | Y21: kisker_akcios_brutto_ft | Z21: Kisker bruttó akciós ár, Ft. | AA21: Akció jelzése: >0 (V14–V16). | AB21: megerositett
A22: /xml/Termek/Min_mennyiseg_nagyker | B22: Min_mennyiseg_nagyker | C22: /xml/Termek | D22: element | E22: 2 | F22: 16 | G22: 1..1 | I22: nem | J22: integer | K22: ^\d+$ | L22: 12433 / 12433 | M22: nem | O22: termek | P22: 12433 | Q22: 12433 | R22: =IF(OR(P22="",Q22="",P22=0),"",Q22/P22) -> 1 | S22: 15 | T22: 1 | U22: 1000 | V22: 4 | W22: 1 | X22: termek | Y22: min_mennyiseg_nagyker | Z22: Minimális nagyker rendelési mennyiség. | AA22: Minimum vagy többszörös? – nyitott kérdés. | AB22: feltetelezes
A23: /xml/Termek/Min_mennyiseg_kisker | B23: Min_mennyiseg_kisker | C23: /xml/Termek | D23: element | E23: 2 | F23: 17 | G23: 1..1 | I23: nem | J23: integer | K23: ^\d+$ | L23: 12433 / 12433 | M23: nem | O23: termek | P23: 12433 | Q23: 12433 | R23: =IF(OR(P23="",Q23="",P23=0),"",Q23/P23) -> 1 | S23: 8 | T23: 0 | U23: 100 | V23: 3 | W23: 1 | X23: termek | Y23: min_mennyiseg_kisker | Z23: Minimális kisker rendelési mennyiség. | AA23: 1 db 0 érték (V20). | AB23: feltetelezes
A24: /xml/Termek/KartonMennyiseg | B24: KartonMennyiseg | C24: /xml/Termek | D24: element | E24: 2 | F24: 18 | G24: 1..1 | I24: nem | J24: integer | K24: ^\d+$ | L24: 12433 / 12433 | M24: nem | O24: termek | P24: 12433 | Q24: 12433 | R24: =IF(OR(P24="",Q24="",P24=0),"",Q24/P24) -> 1 | S24: 121 | T24: 1 | U24: 290000 | V24: 6 | W24: 24 | X24: termek | Y24: karton_mennyiseg | Z24: Hány értékesítési egység van egy gyűjtőkartonban. | AA24: Ömlesztett horgoknál 290 000-ig. | AB24: megerositett
A25: /xml/Termek/KartonSuly | B25: KartonSuly | C25: /xml/Termek | D25: element | E25: 2 | F25: 19 | G25: 1..1 | I25: nem | J25: decimal (4 tizedes, pont) | K25: ^\d+\.\d{4}$ | L25: 12433 / 12433 | M25: nem | N25: 0.0000 = nincs adat | O25: termek | P25: 12433 | Q25: 12433 | R25: =IF(OR(P25="",Q25="",P25=0),"",Q25/P25) -> 1 | S25: 752 | T25: 0 | U25: 377 | V25: 8 | W25: 1.2000 | X25: termek | Y25: karton_suly | Z25: Karton tömege. | AA25: Mértékegység nincs megadva; feltehetően kg. | AB25: feltetelezes
A26: /xml/Termek/KartonTerfogat | B26: KartonTerfogat | C26: /xml/Termek | D26: element | E26: 2 | F26: 20 | G26: 1..1 | I26: nem | J26: decimal (4 tizedes, pont) | K26: ^\d+\.\d{4}$ | L26: 12433 / 12433 | M26: nem | N26: 0.0000 = nincs adat | O26: termek | P26: 12433 | Q26: 12433 | R26: =IF(OR(P26="",Q26="",P26=0),"",Q26/P26) -> 1 | S26: 887 | T26: 0 | U26: 3.168 | V26: 6 | W26: 0.0090 | X26: termek | Y26: karton_terfogat | Z26: Karton térfogata. | AA26: Feltehetően m³ (0.0090 = 9 l). 740 db 0. | AB26: feltetelezes
A27: /xml/Termek/Letrehozas_datuma | B27: Letrehozas_datuma | C27: /xml/Termek | D27: element | E27: 2 | F27: 21 | G27: 1..1 | I27: nem | J27: datetime "YYYY-MM-DD HH:MM:SS" | K27: ^\d{4}-\d{2}-\d{2} \d{2}:\d{2}:\d{2}$ | L27: 12433 / 12433 | M27: nem | N27: "0000-00-00 00:00:00" = ismeretlen | O27: termek | P27: 12433 | Q27: 12433 | R27: =IF(OR(P27="",Q27="",P27=0),"",Q27/P27) -> 1 | S27: 1435 | V27: 19 | W27: 2024-11-11 07:32:44 | X27: termek | Y27: letrehozas_datuma | Z27: A cikk létrehozásának időpontja. | AA27: 1 db érvénytelen (V17). | AB27: megerositett
A28: /xml/Termek/Keszleten | B28: Keszleten | C28: /xml/Termek | D28: element | E28: 2 | F28: 22 | G28: 1..1 | I28: nem | J28: kód (integer) | K28: ^[012]$ | L28: 12433 / 12433 | M28: nem | O28: termek | P28: 12433 | Q28: 12433 | R28: =IF(OR(P28="",Q28="",P28=0),"",Q28/P28) -> 1 | S28: 3 | T28: 0 | U28: 2 | V28: 1 | W28: 1 | X28: termek | Y28: keszleten_kod | Z28: Készletállapot jelző, NEM mennyiség: 0 = nincs, 1 = van, 2 = ? | AA28: A 2-es érték jelentése ismeretlen. | AB28: ismeretlen
A29: /xml/Termek/Termekleiras | B29: Termekleiras | C29: /xml/Termek | D29: element | E29: 2 | F29: 23 | G29: 1..1 | I29: igen | J29: HTML szöveg | M29: igen | N29: nincs leírás | O29: termek | P29: 12433 | Q29: 12386 | R29: =IF(OR(P29="",Q29="",P29=0),"",Q29/P29) -> 0.99621974 | S29: 3484 | V29: 11098 | W29: <p> Wizard Crab </p><p> Egyedi rákutánzat, melyet a legtöbb ragadozó szívesen fogyaszt. </p><p> Jigr | X29: termek | Y29: termekleiras_html | Z29: Termékleírás HTML-ben (<p>, <ul>, <li>, <strong>, <br>…). | AA29: Max 11 098 karakter; nem kell HTML-t tisztítani a nyers oszlopban. | AB29: megerositett
A30: /xml/Termek/Kepek | B30: Kepek | C30: /xml/Termek | D30: element (konténer) | E30: 2 | F30: 24 | G30: 1..1 | I30: nem | J30: konténer | M30: nem | O30: termek | P30: 12433 | R30: =IF(OR(P30="",Q30="",P30=0),"",Q30/P30) | X30: termek_kep | Y30: — | Z30: Képek konténere; mindig van benne legalább 4 Kep. | AB30: megerositett
A31: /xml/Termek/Kepek/Kep | B31: Kepek/Kep | C31: /xml/Termek/Kepek | D31: element (ismétlődő) | E31: 3 | F31: 1 | G31: 4..68 / Termek | H31: @id | I31: nem | J31: url | K31: ^https://images\.energofish\.hu/(thumb|code|small|large|gallery)image/[^/\s]+\.(JPG|jpg|jpeg|JPEG|png|PNG)$ | L31: 68154 / 68166 | M31: igen | N31: az adott képtípus nincs | O31: elem | P31: 81441 | Q31: 68166 | R31: =IF(OR(P31="",Q31="",P31=0),"",Q31/P31) -> 0.83699856 | V31: 60 | W31: https://images.energofish.hu/thumbimage/T10000-330.JPG | X31: termek_kep | Y31: url | Z31: Kép URL. Sorrend fix: thumb, code, small, large, majd gallery1…galleryN folytonosan. | AA31: thumb, small és gallery főtermék-szintű (minden variánsnál ugyanaz); code és large variáns-szintű. 10 URL szóközt tartalmaz, 2 db .WEBP (V35). | AB31: megerositett
A32: /xml/Termek/Kepek/Kep/@id | B32: Kepek/Kep/@id | C32: /xml/Termek/Kepek/Kep | D32: attribute | E32: 4 | F32: attr | G32: 1..1 | I32: nem | J32: kód | M32: nem | O32: elem | P32: 81441 | Q32: 81441 | R32: =IF(OR(P32="",Q32="",P32=0),"",Q32/P32) -> 1 | S32: 68 | V32: 9 | W32: thumb | code | small | large | gallery1…gallery64 | X32: termek_kep | Y32: kep_id, kep_tipus, galeria_sorszam | Z32: A kép típusa; egy Termek-en belül egyedi. | AB32: megerositett
A33: /xml/Termek/Video | B33: Video | C33: /xml/Termek | D33: element | E33: 2 | F33: 25 | G33: 1..1 | I33: részben (ha kitöltött) | J33: url (YouTube) | K33: ^https://(www\.)?(youtube\.com/watch\?v=|youtu\.be/)[\w\-]{11}(&\S*)?$ | L33: 953 / 954 | M33: igen | N33: nincs videó | O33: termek | P33: 12433 | Q33: 954 | R33: =IF(OR(P33="",Q33="",P33=0),"",Q33/P33) -> 0.07673128 | S33: 892 | V33: 73 | W33: https://www.youtube.com/watch?v=0X83mqSyvN0 | X33: termek | Y33: video_url | Z33: Termékvideó URL. | AA33: 9 db extra paraméterrel (&t=, &ab_channel=), 1 db hibás "?feature=share" (V31). | AB33: megerositett
A34: /xml/Termek/Video/@title | B34: Video/@title | C34: /xml/Termek/Video | D34: attribute | E34: 3 | F34: attr | G34: 1..1 | I34: nem | J34: string | M34: igen | N34: nincs videó | O34: termek | P34: 12433 | Q34: 954 | R34: =IF(OR(P34="",Q34="",P34=0),"",Q34/P34) -> 0.07673128 | V34: 100 | W34: Kamasaki Tele Power bot | X34: termek | Y34: video_cim | Z34: Videó címe; pontosan akkor kitöltött, ha az URL is. | AA34: Végén gyakran szóköz → strip. | AB34: megerositett
A35: /xml/Termek/Termek_jellemzok | B35: Termek_jellemzok | C35: /xml/Termek | D35: element (konténer) | E35: 2 | F35: 26 | G35: 1..1 | I35: nem | J35: konténer | M35: nem | O35: termek | P35: 12433 | R35: =IF(OR(P35="",Q35="",P35=0),"",Q35/P35) | X35: termek_jellemzo | Y35: — | Z35: Jellemző-blokkok konténere; 10 890 terméknél üres (csak whitespace). | AB35: megerositett
A36: /xml/Termek/Termek_jellemzok/Jellemzo | B36: Termek_jellemzok/Jellemzo | C36: /xml/Termek/Termek_jellemzok | D36: element (ismétlődő) | E36: 3 | F36: 1 | G36: 0..6 / Termek | H36: @id | I36: igen | J36: string | M36: igen | N36: üres blokk (260 db) | O36: elem | P36: 2928 | Q36: 2668 | R36: =IF(OR(P36="",Q36="",P36=0),"",Q36/P36) -> 0.91120219 | V36: 884 | W36: A úgynevezett SIC (szilícium-karbid) gyűrűk… | X36: termek_jellemzo | Y36: szoveg | Z36: Szabványos technológiai leírásblokk (gyűrű, nyél, karbon…). Csak Horgok, Botok, Zsinórok, Orsók kategóriában; 1 543 termék. | AB36: megerositett
A37: /xml/Termek/Termek_jellemzok/Jellemzo/@id | B37: Termek_jellemzok/Jellemzo/@id | C37: /xml/Termek/Termek_jellemzok/Jellemzo | D37: attribute | E37: 4 | F37: attr | G37: 1..1 | I37: nem | J37: integer | M37: nem | O37: elem | P37: 2928 | Q37: 2928 | R37: =IF(OR(P37="",Q37="",P37=0),"",Q37/P37) -> 1 | S37: 99 | W37: 100 | X37: termek_jellemzo | Y37: jellemzo_id | Z37: A blokk azonosítója (99 féle); terméken belül egyedi. | AB37: megerositett
A38: /xml/Termek/Termek_jellemzok/Jellemzo/@name | B38: Termek_jellemzok/Jellemzo/@name | C38: /xml/Termek/Termek_jellemzok/Jellemzo | D38: attribute | E38: 4 | F38: attr | G38: 1..1 | I38: nem | J38: string | M38: igen | N38: mindig üres | O38: elem | P38: 2928 | Q38: 0 | R38: =IF(OR(P38="",Q38="",P38=0),"",Q38/P38) -> 0 | S38: 1 | V38: 0 | W38: "" | Y38: (nem kerül át) | Z38: Mindig üres – nem hordoz információt. | AB38: megerositett
A39: /xml/Termek/Parameterek | B39: Parameterek | C39: /xml/Termek | D39: element (konténer) | E39: 2 | F39: 27 | G39: 1..1 | I39: nem | J39: konténer | M39: nem | O39: termek | P39: 12433 | R39: =IF(OR(P39="",Q39="",P39=0),"",Q39/P39) | X39: termek_parameter | Y39: — | Z39: Paraméterek konténere; mindig van benne legalább 2 Parameter (a Cikkszám mindig). | AB39: megerositett
A40: /xml/Termek/Parameterek/Parameter | B40: Parameterek/Parameter | C40: /xml/Termek/Parameterek | D40: element (ismétlődő) | E40: 3 | F40: 1 | G40: 2..10 / Termek | H40: @id | I40: igen | J40: string | M40: igen | N40: a sablonban szerepel, de nincs érték | O40: elem | P40: 88439 | Q40: 54597 | R40: =IF(OR(P40="",Q40="",P40=0),"",Q40/P40) -> 0.61734077 | V40: 80 | W40: 12 cm | X40: termek_parameter | Y40: ertek | Z40: Szabad szöveges tulajdonság. Hogy melyik paraméter jelenik meg, a kategória sablonja dönti el. | AA40: Az "Akció" (id=40) a bot akciója, nem árakció! | AB40: megerositett
...

Sheet cel_adatmodell
A1: tabla | B1: oszlop | C1: sorrend | D1: adattipus | E1: nullable | F1: kulcs | G1: forras_relativ_xpath | H1: transzformacio | I1: leiras | J1: statusz
A2: termek | B2: cikkszam | C2: 1 | D2: VARCHAR(8) | E2: nem | F2: PK | G2: Cikkszam | H2: strip; szövegként | I2: Cikkszám kötőjel nélkül | J2: megerositett
A3: termek | B3: cikkszam_k | C3: 2 | D3: VARCHAR(9) | E3: nem | F3: UNIQUE | G3: CikkszamK | H3: strip | I3: Kötőjeles cikkszám | J3: megerositett
A4: termek | B4: termeknev | C4: 3 | D4: VARCHAR(120) | E4: nem | G4: Termeknev | H4: CDATA szöveg, strip | I4: Variáns neve | J4: megerositett
A5: termek | B5: fotermek_id | C5: 4 | D5: INTEGER | E5: nem | F5: FK → fotermek | G5: Fotermek/@id | H5: int() | I5: Főtermék id | J5: megerositett
A6: termek | B6: fotermek_nev | C6: 5 | D6: VARCHAR(120) | E6: nem | G6: Fotermek | H6: strip | I6: Főtermék neve | J6: megerositett
A7: termek | B7: termek_link | C7: 6 | D7: VARCHAR(200) | E7: nem | G7: Termek_link | H7: strip | I7: Főtermék URL | J7: megerositett
A8: termek | B8: vonalkod | C8: 7 | D8: VARCHAR(14) | E8: igen | G8: Vonalkod | H8: strip (NBSP is); "" → NULL; SZÖVEG, nem szám | I8: Elsődleges EAN | J8: megerositett
A9: termek | B9: vonalkod2 | C9: 8 | D9: VARCHAR(14) | E9: igen | G9: Vonalkod2 | H9: strip; ha nem csak számjegy → NULL (+ V09 napló) | I9: Második EAN | J9: megerositett
A10: termek | B10: vtsz | C10: 9 | D10: VARCHAR(10) | E10: igen | G10: VTSZ_SZJ | H10: strip; ha nem csak számjegy → NULL | I10: Vámtarifaszám | J10: megerositett
A11: termek | B11: kategoria_id | C11: 10 | D11: INTEGER | E11: nem | F11: FK → kategoria | G11: Kategoria/@id | H11: int() | I11: Főkategória id | J11: megerositett
A12: termek | B12: kategoria_nev | C12: 11 | D12: VARCHAR(40) | E12: igen | G12: Kategoria | H12: strip; "" → NULL | I12: Főkategória neve | J12: megerositett
A13: termek | B13: alkategoria_id | C13: 12 | D13: INTEGER | E13: nem | F13: FK → alkategoria | G13: Alkategoria/@id | H13: int() | I13: Alkategória id | J13: megerositett
A14: termek | B14: alkategoria_nev | C14: 13 | D14: VARCHAR(40) | E14: nem | G14: Alkategoria | H14: strip ("Feeder " → "Feeder") | I14: Alkategória neve | J14: megerositett
A15: termek | B15: marka | C15: 14 | D15: VARCHAR(40) | E15: nem | G15: Marka_gyarto | H15: strip | I15: Márka | J15: megerositett
A16: termek | B16: nagyker_netto_ft | C16: 15 | D16: INTEGER | E16: nem | G16: Nagyker_netto | H16: int() | I16: Nagyker nettó ár | J16: megerositett
A17: termek | B17: nagyker_akcios_netto_ft | C17: 16 | D17: INTEGER | E17: nem | G17: Nagyker_akcios_netto | H17: int(); a 0 megmarad (= nincs akció) | I17: Nagyker nettó akciós ár | J17: megerositett
A18: termek | B18: kisker_brutto_ft | C18: 17 | D18: INTEGER | E18: nem | G18: Kisker_brutto | H18: int() | I18: Kisker bruttó ár | J18: megerositett
A19: termek | B19: kisker_akcios_brutto_ft | C19: 18 | D19: INTEGER | E19: nem | G19: Kisker_akcios_brutto | H19: int(); a 0 megmarad | I19: Kisker bruttó akciós ár | J19: megerositett
A20: termek | B20: akcios | C20: 19 | D20: BOOLEAN | E20: nem | G20: (származtatott) | H20: nagyker_akcios_netto_ft > 0 OR kisker_akcios_brutto_ft > 0 | I20: Van-e akció | J20: megerositett
A21: termek | B21: min_mennyiseg_nagyker | C21: 20 | D21: INTEGER | E21: nem | G21: Min_mennyiseg_nagyker | H21: int() | I21: Min. rendelés nagyker | J21: feltetelezes
A22: termek | B22: min_mennyiseg_kisker | C22: 21 | D22: INTEGER | E22: nem | G22: Min_mennyiseg_kisker | H22: int() | I22: Min. rendelés kisker | J22: feltetelezes
A23: termek | B23: karton_mennyiseg | C23: 22 | D23: INTEGER | E23: nem | G23: KartonMennyiseg | H23: int() | I23: Db / karton | J23: megerositett
A24: termek | B24: karton_suly | C24: 23 | D24: DECIMAL(10,4) | E24: nem | G24: KartonSuly | H24: Decimal(); a 0 megmarad | I24: Karton tömeg (feltehetően kg) | J24: feltetelezes
A25: termek | B25: karton_terfogat | C25: 24 | D25: DECIMAL(10,4) | E25: nem | G25: KartonTerfogat | H25: Decimal(); a 0 megmarad | I25: Karton térfogat (feltehetően m³) | J25: feltetelezes
... A41: termek | B41: altermek_matrica | C41: 40 | D41: VARCHAR(60) | E41: igen | G41: Altermek_matrica | H41: strip; "" → NULL | I41: Variáns matrica fájlnév | J41: megerositett
A42: termek_kep | B42: cikkszam | C42: 1 | D42: VARCHAR(8) | E42: nem | F42: PK1, FK → termek | G42: ../../Cikkszam | H42: a szülő Termek cikkszáma | J42: megerositett
A43: termek_kep | B43: kep_id | C43: 2 | D43: VARCHAR(10) | E43: nem | F43: PK2 | G43: Kepek/Kep/@id | H43: változatlanul (thumb, code, small, large, gallery1…) | I43: Képazonosító a terméken belül | J43: megerositett
A44: termek_kep | B44: kep_tipus | C44: 3 | D44: VARCHAR(8) | E44: nem | G44: Kepek/Kep/@id | H44: "galleryN" → "gallery", egyébként = kep_id | I44: Képtípus | J44: megerositett
A45: termek_kep | B45: galeria_sorszam | C45: 4 | D45: SMALLINT | E45: igen | G45: Kepek/Kep/@id | H45: "galleryN" → N; egyébként NULL | I45: Galéria sorszám | J45: megerositett
A46: termek_kep | B46: szint | C46: 5 | D46: VARCHAR(10) | E46: nem | G46: (származtatott) | H46: code, large → "variáns"; thumb, small, gallery → "főtermék" | I46: Melyik szintre jellemző a kép | J46: megerositett
A47: termek_kep | B47: sorrend | C47: 6 | D47: SMALLINT | E47: nem | G47: (pozíció) | H47: 1-től számozott pozíció a Kepek-en belül | I47: Eredeti sorrend | J47: megerositett
A48: termek_kep | B48: url | C48: 7 | D48: VARCHAR(200) | E48: nem | G48: Kepek/Kep | H48: strip; ÜRES ELEMBŐL NEM KÉSZÜL SOR; letöltéskor URL-kódolás (szóköz!) | I48: Kép URL | J48: megerositett
A49: termek_parameter | B49: cikkszam | C49: 1 | D49: VARCHAR(8) | E49: nem | F49: PK1, FK → termek | G49: ../../Cikkszam | H49: a szülő Termek cikkszáma | J49: megerositett
A50: termek_parameter | B50: parameter_id | C50: 2 | D50: SMALLINT | E50: nem | F50: PK2 | G50: Parameterek/Parameter/@id | H50: int() | I50: Paraméter id (37 féle) | J50: megerositett
A51: termek_parameter | B51: parameter_nev | C51: 3 | D51: VARCHAR(30) | E51: nem | G51: Parameterek/Parameter/@name | H51: változatlanul | I51: Paraméter név | J51: megerositett
A52: termek_parameter | B52: ertek | C52: 4 | D52: VARCHAR(100) | E52: nem | G52: Parameterek/Parameter | H52: CDATA, strip; ÜRES ÉRTÉKBŐL NEM KÉSZÜL SOR | I52: Paraméter érték (szöveg) | J52: megerositett
A53: termek_parameter | B53: sorrend | C53: 5 | D53: SMALLINT | E53: nem | G53: (pozíció) | H53: 1-től számozott pozíció a Parameterek-en belül (üresekkel együtt számolva) | I53: Eredeti sorrend | J53: megerositett
A54: termek_jellemzo | B54: cikkszam | C54: 1 | D54: VARCHAR(8) | E54: nem | F54: PK1, FK → termek | G54: ../../Cikkszam | H54: a szülő Termek cikkszáma | J54: megerositett
A55: termek_jellemzo | B55: jellemzo_id | C55: 2 | D55: SMALLINT | E55: nem | F55: PK2 | G55: Termek_jellemzok/Jellemzo/@id | H55: int() | I55: Jellemző blokk id (99 féle) | J55: megerositett
...

Sheet validacio
A1: szabaly_id | B1: mezo_xpath | C1: szabaly | D1: ellenorzes | E1: sulyossag | F1: jelenlegi_serules_db | G1: pelda | H1: javasolt_kezeles
A2: V01 | B2: Cikkszam | C2: Cikkszam egyedi a teljes feedben | D2: len(set(cikkszam)) == darab | E2: hiba | F2: 0 | H2: Betöltés megállítása
A3: V02 | B3: Cikkszam, CikkszamK | C3: Cikkszam == CikkszamK kötőjel nélkül | D3: Cikkszam == CikkszamK.replace('-','') | E3: hiba | F3: 0 | H3: Napló
A4: V03 | B4: Parameter[@id=5] | C4: A "Cikkszám" paraméter == CikkszamK | D4: param[5] == CikkszamK | E4: figyelmeztetés | F4: 0 | H4: Napló
A5: V04 | B5: /xml/Termek | C5: Pontosan 37 gyerekelem, a xml_szerkezet szerinti sorrendben | D5: [c.tag for c in termek] == ELVART_SORREND | E5: hiba | F5: 0 | H5: Sémaváltozás → leállítás, értesítés
A6: V05 | B6: Vonalkod | C6: Vonalkod üres | D6: vonalkod is None | E6: info | F6: 111 | G6: 12045-572, 12048-903, 12048-948, 12048-951, 12048-952 | H6: NULL
A7: V06 | B7: Vonalkod | C7: Vonalkod hossza nem 13 | D7: len(vonalkod) != 13 | E7: figyelmeztetés | F7: 30 | G7: 79007-751 (8885905362), 84412-9C5 (818541024689), 84414-1SG (590273031989), 84414-1SH (590306819944) | H7: Megtartani, napló (12 jegyű = valószínűleg UPC-A)
A8: V07 | B8: Vonalkod | C8: EAN-13 ellenőrző számjegy hibás | D8: not ean13_checksum_ok(vonalkod) | E8: figyelmeztetés | F8: 9 | G8: 58273-250 (5996495012919), 74869-070 (1010101007183), 75395-300 (1010101004507), 79456-137 (5998065101379) | H8: Megtartani, napló
A9: V08 | B9: Vonalkod | C9: Szóköz / NBSP az értékben | D9: raw != raw.strip() or "\u00a0" in raw | E9: info | F9: 1 | G9: SNBC0-053 | H9: strip NBSP-vel együtt
A10: V09 | B10: Vonalkod2 | C10: Nem csak számjegy (Excel tudományos alak "5,99821E+12", "ö" elütés a 0 helyett) | D10: not vonalkod2.isdigit() | E10: hiba | F10: 5 | G10: 69720-215 (5,99821E+12), 84415-TTT (59ö273ö319658), 92000-305 (59975563ö3ö59), 92000-321 (6,00E+12), 94042-155 (5999561183öö8) | H10: NULL, napló
A11: V09b | B11: Vonalkod2 | C11: Vonalkod2 == Cikkszam (rossz mezőbe írt cikkszám) | D11: vonalkod2 == cikkszam | E11: figyelmeztetés | F11: 1 | G11: 72092-300 (72092300) | H11: Napló
A12: V10 | B12: VTSZ_SZJ | C12: VTSZ üres | D12: vtsz is None | E12: figyelmeztetés | F12: 10 | G12: 79904-216, SBS15-223, SBS23-520, SBS25-061, SBS25-062 | H12: NULL
A13: V11 | B13: VTSZ_SZJ | C13: VTSZ nem 8 számjegy | D13: not re.fullmatch(r"\d{8}", vtsz) | E13: figyelmeztetés | F13: 3 | G13: BUTOR-031 (..........), SBS13-517 (2308009090), SBS75-662 (2308009090) | H13: csak számjegy → megtartani; egyéb → NULL
A14: V12 | B14: Kategoria | C14: Kategória név üres | D14: kategoria_nev is None | E14: figyelmeztetés | F14: 17 | G14: 75395-316, 75395-317, 75395-318, 75395-319, 75395-320 | H14: NULL (id=1)
A15: V13 | B15: Alkategoria/@id | C15: Alkategoria id nem a Kategoria id-val kezdődik | D15: not str(alk_id).startswith(str(kat_id)) | E15: info | F15: 17 | G15: 75395-316, 75395-317, 75395-318, 75395-319, 75395-320 | H15: Ismert kivétel: 1 → 999
A16: V14 | B16: *_akcios_* | C16: Akciós ár > normál ár | D16: na > nn or ka > kb | E16: hiba | F16: 0 | H16: Napló
A17: V15 | B17: *_akcios_* | C17: Akciós ár = normál ár (és > 0) | D17: (0 < na == nn) or (0 < ka == kb) | E17: figyelmeztetés | F17: 7 | G17: 44853-100, 45315-100, 45315-200, 79009-090, M8167-010, MA411-016, Y2200-022 | H17: Napló
A18: V16 | B18: *_akcios_* | C18: Csak az egyik (nagyker / kisker) akciós ár > 0 | D18: (na > 0) != (ka > 0) | E18: figyelmeztetés | F18: 1 | G18: 43460-990 | H18: Napló
A19: V17 | B19: Letrehozas_datuma | C19: Érvénytelen dátum ("0000-00-00 00:00:00") | D19: strptime hibát dob | E19: hiba | F19: 1 | G19: 80020-002 | H19: NULL
A20: V18 | B20: KartonTerfogat | C20: Karton térfogat = 0 | D20: karton_terfogat == 0 | E20: info | F20: 740 | G20: 11057-699, 12049-063, 12049-064, 12049-066, 12049-067 | H20: Megtartani (0)
A21: V19 | B21: KartonSuly | C21: Karton súly = 0 | D21: karton_suly == 0 | E21: info | F21: 66 | G21: 12049-063, 12049-064, 12049-066, 12049-067, 12049-068 | H21: Megtartani (0)
A22: V20 | B22: Min_mennyiseg_kisker | C22: Minimális kisker mennyiség = 0 | D22: min_mennyiseg_kisker == 0 | E22: figyelmeztetés | F22: 1 | G22: 80126-165 | H22: Napló
A23: V21 | B23: *_egysegar_* | C23: Egységár egysége == Kiszerelesi_egyseg | D23: unit(egysegar) == kiszerelesi_egyseg | E23: hiba | F23: 0 | H23: Napló
A24: V22 | B24: *_egysegar_* | C24: Egységár mezők pontosan akkor üresek, ha Kiszerelesi_egyseg üres | D24: bool(egysegar) == bool(kiszerelesi_egyseg) | E24: hiba | F24: 0 | H24: Napló
A25: V23 | B25: Kepek/Kep/@id | C25: Sorrend: thumb, code, small, large, gallery1…N folytonosan | D25: ids[:4]==[thumb,code,small,large] and gallery folytonos | E25: hiba | F25: 0 | H25: Sémaváltozás → napló
A26: V24 | B26: Kep thumb/small/gallery | C26: Főtermékenként azonos | D26: groupby(fotermek_id) → 1 különböző érték | E26: info | F26: 0 | H26: —
A27: V25 | B27: Termek_link | C27: Főtermékenként azonos | D27: groupby(fotermek_id) → 1 különböző link | E27: figyelmeztetés | F27: 1 | G27: fotermek_id 18489 (Forgo-… és Aprocikk-… link) | H27: fotermek dimenzióban az első
A28: V26 | B28: Parameter/@id, Jellemzo/@id | C28: Terméken belül egyedi | D28: len(ids) == len(set(ids)) | E28: hiba | F28: 0 | H28: PK sérülne → napló
A29: V27 | B29: Jellemzo/@name | C29: Mindig üres | D29: name == "" | E29: info | F29: 2928 | H29: Nem kerül át
A30: V28 | B30: szöveges mezők | C30: Eleji/végi whitespace | D30: raw != raw.strip() | E30: info | F30: 1011 | G30: 10731-300, 11001-200, 11043-541, 11045-500, 11045-501 | H30: strip
A31: V29 | B31: Ertekesitesi_egyseg | C31: Nem "DB" | D31: ertekesitesi_egyseg != "DB" | E31: info | F31: 1 | G31: 99001-001 | H31: Megtartani
A32: V30 | B32: Kisker_brutto, Nagyker_netto | C32: Kisker nettó < nagyker nettó (negatív árrés) | D32: kisker_brutto / 1.27 < nagyker_netto | E32: figyelmeztetés | F32: 5 | G32: 12302-397, 12341-395, 12341-396, 12341-397, 80001-998 | H32: Napló
A33: V31 | B33: Video | C33: URL extra paraméterrel vagy hibásan ("?feature=share") | D33: not re.fullmatch(r"https://(www\.)?youtube\.com/watch\?v=[\w-]{11}", url) | E33: info | F33: 10 | G33: 20155-851 (…?feature=share) | H33: Videó id kinyerése: v= utáni 11 karakter
A34: V32 | B34: Video, Video/@title | C34: URL és cím együtt kitöltött | D34: bool(video_url) == bool(video_cim) | E34: info | F34: 0 | H34: —
A35: V33 | B35: Alkategoria/@id | C35: id → egyetlen név és kategória | D35: groupby(alk_id) → 1 (nev, kat_id) | E35: hiba | F35: 0 | H35: Dimenzió nem építhető → napló
A36: V34 | B36: Keszleten, Alacsony_keszlet, Katalogus_info, Kiszerelesi_egyseg | C36: Értékkészlet a kodlistak lap szerinti | D36: value in KODLISTA[mezo] | E36: hiba | F36: 0 | H36: Új kód → napló, értesítés
A37: V35 | B37: Kepek/Kep | C37: URL szóközt tartalmaz / nem JPG | D37: " " in url or not url.lower().endswith((".jpg",".png")) | E37: info | F37: 12 | G37: 72151-420, 98015-843 (szóköz); 12049-110 (.WEBP) | H37: Letöltéskor urllib.parse.quote

Sheet kodlistak
A1: mezo | B1: ertek | C1: darab | D1: arany | E1: jelentes | F1: statusz
A2: Keszleten | B2: 1 | C2: 10887 | D2: =IF(README!$B$9=0,"",C2/README!$B$9) -> 0.8756535 | E2: készleten | F2: megerositett
A3: Keszleten | B3: 0 | C3: 1183 | D3: =IF(README!$B$9=0,"",C3/README!$B$9) -> 0.095150004 | E3: nincs készleten | F3: megerositett
A4: Keszleten | B4: 2 | C4: 363 | D4: =IF(README!$B$9=0,"",C4/README!$B$9) -> 0.029196493 | E4: ismeretlen | F4: ismeretlen
A5: Alacsony_keszlet | B5: 1 | C5: 6506 | D5: =IF(README!$B$9=0,"",C5/README!$B$9) -> 0.52328481 | E5: alacsony készlet | F5: feltetelezes
A6: Alacsony_keszlet | B6: 0 | C6: 5927 | D6: =IF(README!$B$9=0,"",C6/README!$B$9) -> 0.47671519 | E6: nem alacsony | F6: feltetelezes
A7: Katalogus_info | B7: (üres) | C7: 8620 | D7: =IF(README!$B$9=0,"",C7/README!$B$9) -> 0.69331617 | E7: nincs jelölés | F7: megerositett
A8: Katalogus_info | B8: N | C8: 2063 | D8: =IF(README!$B$9=0,"",C8/README!$B$9) -> 0.16592938 | E8: ismeretlen | F8: ismeretlen
A9: Katalogus_info | B9: K | C9: 1750 | D9: =IF(README!$B$9=0,"",C9/README!$B$9) -> 0.14075444 | E9: ismeretlen | F9: ismeretlen
A10: Ertekesitesi_egyseg | B10: DB | C10: 12432 | D10: =IF(README!$B$9=0,"",C10/README!$B$9) -> 0.99991957 | E10: darab | F10: megerositett
A11: Ertekesitesi_egyseg | B11: L | C11: 1 | D11: =IF(README!$B$9=0,"",C11/README!$B$9) -> 8.0431111e-05 | E11: liter | F11: feltetelezes
A12: Kiszerelesi_egyseg | B12: DB | C12: 4710 | D12: =IF(README!$B$9=0,"",C12/README!$B$9) -> 0.37883053 | E12: darab | F12: megerositett
A13: Kiszerelesi_egyseg | B13: (üres) | C13: 4628 | D13: =IF(README!$B$9=0,"",C13/README!$B$9) -> 0.37223518 | E13: nincs egységár | F13: megerositett
... A40: Altermek_matrica | B40: 50s_MOHOSZ_elektronikai_thumb.png | C40: 1 | D40: =IF(README!$B$9=0,"",C40/README!$B$9) -> 8.0431111e-05 | E40: MOHOSZ jelölés: elektronikai | F40: feltetelezes
A41: Min_mennyiseg_nagyker | B41: 1 | C41: 11042 | D41: =IF(README!$B$9=0,"",C41/README!$B$9) -> 0.88812032
A42: Min_mennyiseg_nagyker | B42: 2 | C42: 35 | D42: =IF(README!$B$9=0,"",C42/README!$B$9) -> 0.0028150889
A43: Min_mennyiseg_nagyker | B43: 3 | C43: 15 | D43: =IF(README!$B$9=0,"",C43/README!$B$9) -> 0.0012064667
A44: Min_mennyiseg_nagyker | B44: 4 | C44: 3 | D44: =IF(README!$B$9=0,"",C44/README!$B$9) -> 0.00024129333
A45: Min_mennyiseg_nagyker | B45: 5 | C45: 347 | D45: =IF(README!$B$9=0,"",C45/README!$B$9) -> 0.027909595
A46: Min_mennyiseg_nagyker | B46: 10 | C46: 738 | D46: =IF(README!$B$9=0,"",C46/README!$B$9) -> 0.05935816
A47: Min_mennyiseg_nagyker | B47: 12 | C47: 5 | D47: =IF(README!$B$9=0,"",C47/README!$B$9) -> 0.00040215555
A48: Min_mennyiseg_nagyker | B48: 20 | C48: 6 | D48: =IF(README!$B$9=0,"",C48/README!$B$9) -> 0.00048258666
A49: Min_mennyiseg_nagyker | B49: 24 | C49: 5 | D49: =IF(README!$B$9=0,"",C49/README!$B$9) -> 0.00040215555
A50: Min_mennyiseg_nagyker | B50: 25 | C50: 141 | D50: =IF(README!$B$9=0,"",C50/README!$B$9) -> 0.011340787
A51: Min_mennyiseg_nagyker | B51: 48 | C51: 6 | D51: =IF(README!$B$9=0,"",C51/README!$B$9) -> 0.00048258666
A52: Min_mennyiseg_nagyker | B52: 50 | C52: 53 | D52: =IF(README!$B$9=0,"",C52/README!$B$9) -> 0.0042628489
... A63: Min_mennyiseg_kisker | B63: 100 | C63: 6 | D63: =IF(README!$B$9=0,"",C63/README!$B$9) -> 0.00048258666
A64: Kep/@id | B64: thumb | C64: 12433 | D64: =IF(README!$B$9=0,"",C64/README!$B$9) -> 1 | E64: bélyegkép, főtermék-szintű (nem üres: 12 410) | F64: megerositett
A65: Kep/@id | B65: code | C65: 12433 | D65: =IF(README!$B$9=0,"",C65/README!$B$9) -> 1 | E65: variáns képe (nem üres: 6 007) | F65: megerositett
A66: Kep/@id | B66: small | C66: 12433 | D66: =IF(README!$B$9=0,"",C66/README!$B$9) -> 1 | E66: kis kép, főtermék-szintű (nem üres: 12 411) | F66: megerositett
A67: Kep/@id | B67: large | C67: 12433 | D67: =IF(README!$B$9=0,"",C67/README!$B$9) -> 1 | E67: nagy kép, variáns-szintű (nem üres: 5 629) | F67: megerositett
A68: Kep/@id | B68: gallery1 … gallery64 | C68: 5423 | D68: =IF(README!$B$9=0,"",C68/README!$B$9) -> 0.43617791 | E68: galériakép, főtermék-szintű; a darab = legalább 1 galériaképes termék; max 64 kép | F68: megerositett

Sheet kategoriak
A1: kategoria_id | B1: kategoria_nev | C1: alkategoria_id | D1: alkategoria_nev | E1: termek_db
A2: 1 | C2: 999 | D2: Alap | E2: 17
A3: 3 | B3: Ajándéktárgyak | C3: 3002 | D3: Ajándéktárgy | E3: 33
A4: 3 | B4: Ajándéktárgyak | C4: 3010 | D4: HALAS PÁRNA | E4: 55
A5: 5 | B5: Akció | C5: 5010 | D5: Akciók, szettek | E5: 6
A6: 5 | B6: Akció | C6: 5040 | D6: Kapcsolt termékek | E6: 55
A7: 10 | B7: Botok | C7: 10010 | D7: Rakós | E7: 6
A8: 10 | B8: Botok | C8: 10020 | D8: Spicc | E8: 50
A9: 10 | B9: Botok | C9: 10030 | D9: Bolognai bot | E9: 59
A10: 10 | B10: Botok | C10: 10040 | D10: Match | E10: 14
A11: 10 | B11: Botok | C11: 10050 | D11: Feeder, picker | E11: 102
A12: 10 | B12: Botok | C12: 10060 | D12: Bojlis | E12: 35
A13: 10 | B13: Botok | C13: 10070 | D13: Általános 2-3 részes | E13: 6
A14: 10 | B14: Botok | C14: 10080 | D14: Általános teleszkópos | E14: 25
... A207: 260 | B207: Tómonitoring | C207: 260030 | D207: Kiegészítők | E207: 2

Sheet parameterek
A1: parameter_id | B1: parameter_nev | C1: javasolt_oszlopnev | D1: elofordul_db | E1: nem_ures_db | F1: kitoltottseg | G1: max_hossz | H1: leggyakoribb_ertekek (db) | I1: megjegyzes | J1: statusz
A2: 1 | B2: Átmérő | C2: param_atmero | D2: 946 | E2: 904 | F2: =IF(D2=0,"",E2/D2) -> 0.95560254 | G2: 19 | H2: 0,25 mm (91); 0,20 mm (82); 0,30 mm (79); 0,35 mm (68); 0,40 mm (51) | J2: megerositett
A3: 2 | B3: Áttétel | C3: param_attetel | D3: 118 | E3: 112 | F3: =IF(D3=0,"",E3/D3) -> 0.94915254 | G3: 6 | H3: 5,2:1 (33); 5.1:1 (11); 4,1:1 (10); 5.2:1 (9); 5,0:1 (7) | J3: megerositett
A4: 3 | B4: Antenna | C4: param_antenna | D4: 656 | E4: 430 | F4: =IF(D4=0,"",E4/D4) -> 0.6554878 | G4: 25 | H4: Cserélhető (111); Fix (85); műanyag (80); Műanyag (30); Üveg (25) | J4: megerositett
A5: 4 | B5: Anyaga | C5: param_anyaga | D5: 3616 | E5: 1708 | F5: =IF(D5=0,"",E5/D5) -> 0.47234513 | G5: 62 | H5: Balsa (302); Ólom (186); PU (136); Ólom + műanyag (115); Műanyag (96) | J5: megerositett
A6: 5 | B6: Cikkszám | C6: param_cikkszam | D6: 12433 | E6: 12433 | F6: =IF(D6=0,"",E6/D6) -> 1 | G6: 9 | H6: 10000-327 (1); 10000-328 (1); 10000-330 (1); 10000-335 (1); 10000-341 (1) | I6: Mindig jelen, = CikkszamK (redundáns). | J6: megerositett
A7: 6 | B7: Csapágy | C7: param_csapagy | D7: 118 | E7: 107 | F7: =IF(D7=0,"",E7/D7) -> 0.90677966 | G7: 4 | H7: 5+1 (37); 7+1 (26); 3+1 (9); 6+1 (8); 1 (6) | J7: megerositett
A8: 7 | B8: Dobósúly | C8: param_dobosuly | D8: 447 | E8: 403 | F8: =IF(D8=0,"",E8/D8) -> 0.901566 | G8: 24 | H8: 5-20 g (17); 3,5 lbs (16); 5-35 g (12); 40-80 g (10); 10-30 g (10) | J8: megerositett
A9: 8 | B9: Egyéb | C9: param_egyeb | D9: 88 | E9: 53 | F9: =IF(D9=0,"",E9/D9) -> 0.60227273 | G9: 24 | H9: Cyprinus carpio (6); Esox lucius (3); Sander lucioperca (3); Thunnus thynnus (3); Ctenopharyngodon idella (3) | J9: megerositett
A10: 9 | B10: Elosztása | C10: param_elosztasa | D10: 175 | E10: 51 | F10: =IF(D10=0,"",E10/D10) -> 0.29142857 | G10: 35 | H10: 2 rekeszes (16); 3 rekeszes (10); 3 bothoz (3); 3 tálcás kivitel (2); Fix tálcákkal (2) | J10: megerositett
A11: 10 | B11: Erőforrás | C11: param_eroforras | D11: 119 | E11: 48 | F11: =IF(D11=0,"",E11/D11) -> 0.40336134 | G11: 26 | H11: 2,5 mm standard csatlakozó (12); 211 elem (12); 9V elem (8); 311 elem (5); 435 elem (4) | J11: megerositett
A12: 11 | B12: Fékrendszer | C12: param_fekrendszer | D12: 118 | E12: 112 | F12: =IF(D12=0,"",E12/D12) -> 0.94915254 | G12: 21 | H12: Elsőfék (81); Elsőfék + Nyeletőfék (14); Elsőfék + nyeletőfék (5); Első gyorsfék (4); FD és nyeletőfék (2) | J12: megerositett
A13: 13 | B13: Felület | C13: param_felulet | D13: 832 | E13: 375 | F13: =IF(D13=0,"",E13/D13) -> 0.45072115 | G13: 14 | H13: Natúr (135); Színezett (78); Festett (54); Szinterezett (33); Fekete szinter (29) | J13: megerositett
A14: 15 | B14: Hatótávolság | C14: param_hatotavolsag | D14: 547 | E14: 8 | F14: =IF(D14=0,"",E14/D14) -> 0.014625229 | G14: 18 | H14: 150-200 m (3); 20-30 m (2); 200 m (1); 60 - 70 m (1); 50-60 m távolságig (1) | J14: megerositett
A15: 16 | B15: Horogméret | C15: param_horogmeret | D15: 2214 | E15: 580 | F15: =IF(D15=0,"",E15/D15) -> 0.26196929 | G15: 20 | H15: No. 8 (81); No. 4 (61); No. 10 (38); No. 6 (32); 1/0 (29) | J15: megerositett
A16: 17 | B16: Hossz | C16: param_hossz | D16: 2529 | E16: 1586 | F16: =IF(D16=0,"",E16/D16) -> 0.62712535 | G16: 35 | H16: 300 m (188); 150 m (160); 50 m (103); 600 m (81); 10 m (61) | J16: megerositett
A17: 18 | B17: Jellemző | C17: param_jellemzo | D17: 5130 | E17: 1432 | F17: =IF(D17=0,"",E17/D17) -> 0.2791423 | G17: 80 | H17: M1 (40); M4 (29); Strawberry Jam (28); C1 (27); Ace Lobworm (26) | J17: megerositett
A18: 19 | B18: Kiszerelés | C18: param_kiszereles | D18: 9689 | E18: 5882 | F18: =IF(D18=0,"",E18/D18) -> 0.60708019 | G18: 58 | H18: 10 db/csomag (689); 3 db/csomag (318); 5 db/csomag (310); 1 kg (304); 6 db/csomag (297) | I18: Kiszerelés szövegesen ("10 db/csomag") – az egységár szorzója innen olvasható ki. | J18: megerositett
A19: 20 | B19: Kivitel | C19: param_kivitel | D19: 1488 | E19: 904 | F19: =IF(D19=0,"",E19/D19) -> 0.60752688 | G19: 37 | H19: Csúszó (229); Fix (173); Forgós (73); Inline (63); Füles (39) | J19: megerositett
A20: 21 | B20: Méret | C20: param_meret | D20: 11894 | E20: 8536 | F20: =IF(D20=0,"",E20/D20) -> 0.71767278 | G20: 63 | H20: 2 (219); 8 (210); 4 (201); 5 cm (199); 6 (197) | J20: megerositett
A21: 22 | B21: Max LE | C21: param_max_le | D21: 14 | E21: 1 | F21: =IF(D21=0,"",E21/D21) -> 0.071428571 | G21: 6 | H21: 66 lbs (1) | J21: megerositett
A22: 23 | B22: Merülési szint (m) | C22: param_merulesi_szint_m | D22: 2023 | E22: 506 | F22: =IF(D22=0,"",E22/D22) -> 0.25012358 | G22: 19 | H22: 1 m (101); 0,5 m (62); 1,5 m (56); 2 m (42); 1,8/3,4m (30) | I22: A név tartalmazza a mértékegységet. | J22: megerositett
A23: 24 | B23: Nyél tag | C23: param_nyel_tag | D23: 181 | E23: 13 | F23: =IF(D23=0,"",E23/D23) -> 0.071823204 | G23: 15 | H23: 1 (4); 2 (4); Full karbon (3); 180 cm 2 részes (1); 3 (1) | J23: megerositett
A24: 25 | B24: Orsódob | C24: param_orsodob | D24: 118 | E24: 106 | F24: =IF(D24=0,"",E24/D24) -> 0.89830508 | G24: 49 | H24: Alumínium (53); Alumínium + Grafit pótdob (22); Grafit (10); Fém (4); Könnyített fém (2) | J24: megerositett
A25: 26 | B25: Orsóház anyaga | C25: param_orsohaz_anyaga | D25: 118 | E25: 109 | F25: =IF(D25=0,"",E25/D25) -> 0.92372881 | G25: 24 | H25: Grafit (103); Fém (4); Extra szilárdságú grafit (2) | J25: megerositett
A26: 28 | B26: Súly | C26: param_suly | D26: 2782 | E26: 1926 | F26: =IF(D26=0,"",E26/D26) -> 0.69230769 | G26: 7 | H26: 3 g (98); 7 g (98); 8 g (92); 10 g (87); 14 g (81) | J26: megerositett
A27: 29 | B27: Szállítási méret | C27: param_szallitasi_meret | D27: 696 | E27: 392 | F27: =IF(D27=0,"",E27/D27) -> 0.56321839 | G27: 16 | H27: 126 cm (35); 125 cm (23); 137 cm (18); 136 cm (18); 127 cm (14) | J27: megerositett
A28: 30 | B28: Szár | C28: param_szar | D28: 656 | E28: 444 | F28: =IF(D28=0,"",E28/D28) -> 0.67682927 | G28: 21 | H28: Üvegszál (186); műanyag (80); üveg (33); Műanyag (26); Acél (22) | J28: megerositett
A29: 31 | B29: Szín | C29: param_szin | D29: 9222 | E29: 3559 | F29: =IF(D29=0,"",E29/D29) -> 0.38592496 | G29: 49 | H29: BN (169); Fekete (143); Transzparens (115); Piros (102); Sárga (94) | J29: megerositett
A30: 32 | B30: Szakítószilárdság | C30: param_szakitoszilardsag | D30: 1226 | E30: 929 | F30: =IF(D30=0,"",E30/D30) -> 0.75774878 | G30: 32 | H30: 6,5 kg (18); 15 kg (13); 9 kg (11); 14,90 kg (10); 6 kg (10) | J30: megerositett
A31: 33 | B31: Típus | C31: param_tipus | D31: 9007 | E31: 7508 | F31: =IF(D31=0,"",E31/D31) -> 0.83357389 | G31: 54 | H31: Ball Jig Head (121); SHAD (50); Master (43); Micro jig (40); Legend Jig (34) | J31: megerositett
A32: 34 | B32: Tagok száma | C32: param_tagok_szama | D32: 628 | E32: 373 | F32: =IF(D32=0,"",E32/D32) -> 0.59394904 | G32: 5 | H32: 2 (171); 3+3 (49); 3 (38); 6 (21); 3+2 (20) | J32: megerositett
A33: 35 | B33: Tartalom | C33: param_tartalom | D33: 559 | E33: 33 | F33: =IF(D33=0,"",E33/D33) -> 0.059033989 | G33: 61 | H33: Fejlámpa + Töltőkábel (6); Radar, vezeték nélküli szonár + kiegészítők (2); Radar, vezetékes szonár, vezeték nélküli szonár + kiegészítők (2); Radar, vezetékes szonár + kiegészítők (2); Lámpa + USB kábel (2) | J33: megerositett
A34: 36 | B34: Terhelhetőség | C34: param_terhelhetoseg | D34: 1320 | E34: 115 | F34: =IF(D34=0,"",E34/D34) -> 0.087121212 | G34: 31 | H34: 50 kg (6); 9 kg (6); 70 kg (5); 90 kg (5); 60 kg (4) | J34: megerositett
... A37: 39 | B37: Ízesítés | C37: param_izesites | D37: 2296 | E37: 1217 | F37: =IF(D37=0,"",E37/D37) -> 0.53005226 | G37: 30 | H37: Mangó (37); Ananász (32); Fokhagyma (28); Eper (24); Méz (20) | J37: megerositett
A38: 40 | B38: Akció | C38: param_akcio | D38: 447 | E38: 183 | F38: =IF(D38=0,"",E38/D38) -> 0.40939597 | G38: 13 | H38: B (113); Fast (17); C (16); Regular (6); L (5) | I38: A BOT AKCIÓJA (Fast, B, C, UL…), NEM árakció. | J38: feltetelezes

Sheet xml_minta
A1: minta_cikkszam_k | B1: sor | C1: behuzas_tab | D1: xml_sor (a vezető tabok nélkül)
A2: 10000-327 | B2: 1 | C2: 0 | D2: <Termek>
A3: 10000-327 | B3: 2 | C3: 1 | D3: <Cikkszam>10000327</Cikkszam>
A4: 10000-327 | B4: 3 | C4: 1 | D4: <CikkszamK>10000-327</CikkszamK>
A5: 10000-327 | B5: 4 | C5: 1 | D5: <Termeknev><![CDATA[CRAB RED 12CM]]></Termeknev>
A6: 10000-327 | B6: 5 | C6: 1 | D6: <Fotermek id="24021"><![CDATA[WIZARD CRAB]]></Fotermek>
A7: 10000-327 | B7: 6 | C7: 1 | D7: <Termek_link>https://energofish.hu/product.php/Mucsali-WIZARD-CRAB/24021/</Termek_link>
A8: 10000-327 | B8: 7 | C8: 1 | D8: <Vonalkod>5999018248267</Vonalkod>
A9: 10000-327 | B9: 8 | C9: 1 | D9: <Vonalkod2></Vonalkod2>
A10: 10000-327 | B10: 9 | C10: 1 | D10: <VTSZ_SZJ>95079000</VTSZ_SZJ>
A11: 10000-327 | B11: 10 | C11: 1 | D11: <Kategoria id="210"><![CDATA[Műcsali]]></Kategoria>
A12: 10000-327 | B12: 11 | C12: 1 | D12: <Alkategoria id="210040"><![CDATA[Gumihal]]></Alkategoria>
A13: 10000-327 | B13: 12 | C13: 1 | D13: <Marka_gyarto><![CDATA[Arno]]></Marka_gyarto>
... A121: 10729-300 | B121: 62 | C121: 0 | D121: </Termek>

Sheet minta_termek
A1: cikkszam | B1: cikkszam_k | C1: termeknev | D1: fotermek_id | E1: fotermek_nev | F1: termek_link | G1: vonalkod | H1: vonalkod2 | I1: vtsz | J1: kategoria_id | K1: kategoria_nev | L1: alkategoria_id | M1: alkategoria_nev | N1: marka | O1: nagyker_netto_ft | P1: nagyker_akcios_netto_ft | Q1: kisker_brutto_ft | R1: kisker_akcios_brutto_ft | S1: akcios | T1: min_mennyiseg_nagyker | U1: min_mennyiseg_kisker | V1: karton_mennyiseg | W1: karton_suly | X1: karton_terfogat | Y1: letrehozas_datuma | Z1: keszleten_kod | AA1: termekleiras_html | AB1: video_url | AC1: video_cim | AD1: nagyker_egysegar_netto_ft | AE1: nagyker_akcios_egysegar_netto_ft | AF1: kisker_egysegar_brutto_ft | AG1: kisker_akcios_egysegar_brutto_ft | AH1: egysegar_egyseg | AI1: ertekesitesi_egyseg | AJ1: kiszerelesi_egyseg | AK1: katalogus_info | AL1: alacsony_keszlet | AM1: fotermek_matrica | AN1: altermek_matrica
A2: 10000327 | B2: 10000-327 | C2: CRAB RED 12CM | D2: 24021 | E2: WIZARD CRAB | F2: https://energofish.hu/product.php/Mucsali-WIZARD-CRAB/24021/ | G2: 5999018248267 | I2: 95079000 | J2: 210 | K2: Műcsali | L2: 210040 | M2: Gumihal | N2: Arno | O2: 395 | P2: 320 | Q2: 690 | R2: 530 | S2: =TRUE() -> TRUE | T2: 1 | U2: 1 | V2: 24 | W2: 1.2 | X2: 0.009 | Y2: 45607.314 | Z2: 1 | AA2: <p> Wizard Crab </p><p> Egyedi rákutánzat, melyet a legtöbb ragadozó szívesen fogyaszt. </p><p> Jigre vagy offsetes - chebus módszerrel is feltűzhető</p> | AD2: 395 | AE2: 320 | AF2: 690 | AG2: 530 | AH2: DB | AI2: DB | AJ2: DB | AK2: K | AL2: =TRUE() -> TRUE | AM2: 56p_kifuto_plecsni.png | AN2: 56s_kifuto_plecsni.png
A3: 10000328 | B3: 10000-328 | C3: CRAB RED 8CM | D3: 24021 | E3: WIZARD CRAB | F3: https://energofish.hu/product.php/Mucsali-WIZARD-CRAB/24021/ | G3: 5999018248274 | I3: 95079000 | J3: 210 | K3: Műcsali | L3: 210040 | M3: Gumihal | N3: Arno | O3: 395 | P3: 280 | Q3: 690 | R3: 470 | S3: =TRUE() -> TRUE | T3: 1 | U3: 1 | V3: 24 | W3: 1.2 | X3: 0.009 | Y3: 45607.314 | Z3: 1 | AA3: <p> Wizard Crab </p><p> Egyedi rákutánzat, melyet a legtöbb ragadozó szívesen fogyaszt. </p><p> Jigre vagy offsetes - chebus módszerrel is feltűzhető</p> | AD3: 395 | AE3: 280 | AF3: 690 | AG3: 470 | AH3: DB | AI3: DB | AJ3: DB | AK3: K | AL3: =TRUE() -> TRUE | AM3: 56p_kifuto_plecsni.png | AN3: 56s_kifuto_plecsni.png
A4: 10000330 | B4: 10000-330 | C4: CRAB ORANGE 8CM | D4: 24021 | E4: WIZARD CRAB | F4: https://energofish.hu/product.php/Mucsali-WIZARD-CRAB/24021/ | G4: 5999018248281 | I4: 95079000 | J4: 210 | K4: Műcsali | L4: 210040 | M4: Gumihal | N4: Arno | O4: 395 | P4: 300 | Q4: 690 | R4: 510 | S4: =TRUE() -> TRUE | T4: 1 | U4: 1 | V4: 24 | W4: 1.2 | X4: 0.009 | Y4: 45607.314 | Z4: 1 | AA4: <p> Wizard Crab </p><p> Egyedi rákutánzat, melyet a legtöbb ragadozó szívesen fogyaszt. </p><p> Jigre vagy offsetes - chebus módszerrel is feltűzhető</p> | AD4: 395 | AE4: 300 | AF4: 690 | AG4: 510 | AH4: DB | AI4: DB | AJ4: DB | AK4: K | AL4: =TRUE() -> TRUE | AM4: 56p_kifuto_plecsni.png | AN4: 56s_kifuto_plecsni.png
A5: 10000335 | B5: 10000-335 | C5: ARNO STRIKE MINNOW BROWN 10CM 10PCS/BAG | D5: 24341 | E5: ARNO SPHERE MINNOW | F5: https://energofish.hu/product.php/Mucsali-ARNO-SPHERE-MINNOW/24341/ | G5: 5999018251205 | I5: 95079000 | J5: 210 | K5: Műcsali | L5: 210040 | M5: Gumihal | N5: Arno | O5: 600 | P5: 540 | Q5: 1050 | R5: 910 | S5: =TRUE() -> TRUE | T5: 1 | U5: 1 | V5: 50 | W5: 1.2 | X5: 0.009 | Y5: 45673.426 | Z5: 1 | AA5: <p open="" size:="" style="box-sizing: border-box; margin: 0px 0px 10px; overflow-wrap: break-word; color: rgb(65, 66, 66);"> Ennek a csalinak lágyabb anyaga van és egy igazán érdekes testtel van ellátva, így a nagyobb halakra való horgászathoz is jó alternatíva.</p><p open="" size:="" style="box-sizing: border-box; margin: 0px 0px 10px; overflow-wrap: break-word; color: rgb(65, 66, 66);"> Csukára és süllőre is jó választás! Akár Dropshot módszerhez is.</p> | AD5: 60 | AE5: 54 | AF5: 105 | AG5: 91 | AH5: DB | AI5: DB | AJ5: DB | AK5: K | AL5: =FALSE() -> FALSE | AM5: 56p_kifuto_plecsni.png | AN5: 56s_kifuto_plecsni.png
A6: 10000341 | B6: 10000-341 | C6: ARNO SPHERE MINNOW BLACK-YELLOW 11CM 10PCS/BAG | D6: 24341 | E6: ARNO SPHERE MINNOW | F6: https://energofish.hu/product.php/Mucsali-ARNO-SPHERE-MINNOW/24341/ | G6: 5999018252080 | I6: 95079000 | J6: 210 | K6: Műcsali | L6: 210040 | M6: Gumihal | N6: Arno | O6: 600 | P6: 360 | Q6: 1050 | R6: 610 | S6: =TRUE() -> TRUE | T6: 1 | U6: 1 | V6: 40 | W6: 2.8 | X6: 0.009 | Y6: 45716.411 | Z6: 1 | AA6: <p open="" size:="" style="box-sizing: border-box; margin: 0px 0px 10px; overflow-wrap: break-word; color: rgb(65, 66, 66);"> Ennek a csalinak lágyabb anyaga van és egy igazán érdekes testtel van ellátva, így a nagyobb halakra való horgászathoz is jó alternatíva.</p><p open="" size:="" style="box-sizing: border-box; margin: 0px 0px 10px; overflow-wrap: break-word; color: rgb(65, 66, 66);"> Csukára és süllőre is jó választás! Akár Dropshot módszerhez is.</p> | AD6: 60 | AE6: 36 | AF6: 105 | AG6: 61 | AH6: DB | AI6: DB | AJ6: DB | AK6: K | AL6: =TRUE() -> TRUE | AM6: 56p_kifuto_plecsni.png | AN6: 56s_kifuto_plecsni.png
A7: 10000342 | B7: 10000-342 | C7: ARNO SPHERE MINNOW WHITE-YELLOW 11CM 10PCS/BAG | D7: 24341 | E7: ARNO SPHERE MINNOW | F7: https://energofish.hu/product.php/Mucsali-ARNO-SPHERE-MINNOW/24341/ | G7: 5999018252097 | I7: 95079000 | J7: 210 | K7: Műcsali | L7: 210040 | M7: Gumihal | N7: Arno | O7: 600 | P7: 370 | Q7: 1050 | R7: 630 | S7: =TRUE() -> TRUE | T7: 1 | U7: 1 | V7: 40 | W7: 2 | X7: 0.009 | Y7: 45716.411 | Z7: 1 | AA7: <p open="" size:="" style="box-sizing: border-box; margin: 0px 0px 10px; overflow-wrap: break-word; color: rgb(65, 66, 66);"> Ennek a csalinak lágyabb anyaga van és egy igazán érdekes testtel van ellátva, így a nagyobb halakra való horgászathoz is jó alternatíva.</p><p open="" size:="" style="box-sizing: border-box; margin: 0px 0px 10px; overflow-wrap: break-word; color: rgb(65, 66, 66);"> Csukára és süllőre is jó választás! Akár Dropshot módszerhez is.</p> | AD7: 60 | AE7: 37 | AF7: 105 | AG7: 63 | AH7: DB | AI7: DB | AJ7: DB | AK7: K | AL7: =TRUE() -> TRUE | AM7: 56p_kifuto_plecsni.png | AN7: 56s_kifuto_plecsni.png
A8: 10000344 | B8: 10000-344 | C8: ARNO SPHERE MINNOW CLARET-YELLOW 11CM 10PCS/BAG | D8: 24341 | E8: ARNO SPHERE MINNOW | F8: https://energofish.hu/product.php/Mucsali-ARNO-SPHERE-MINNOW/24341/ | G8: 5999018252110 | I8: 95079000 | J8: 210 | K8: Műcsali | L8: 210040 | M8: Gumihal | N8: Arno | O8: 600 | P8: 360 | Q8: 1050 | R8: 600 | S8: =TRUE() -> TRUE | T8: 1 | U8: 1 | V8: 50 | W8: 2 | X8: 0.009 | Y8: 45716.411 | Z8: 1 | AA8: <p open="" size:="" style="box-sizing: border-box; margin: 0px 0px 10px; overflow-wrap: break-word; color: rgb(65, 66, 66);"> Ennek a csalinak lágyabb anyaga van és egy igazán érdekes testtel van ellátva, így a nagyobb halakra való horgászathoz is jó alternatíva.</p><p open="" size:="" style="box-sizing: border-box; margin: 0px 0px 10px; overflow-wrap: break-word; color: rgb(65, 66, 66);"> Csukára és süllőre is jó választás! Akár Dropshot módszerhez is.</p> | AD8: 60 | AE8: 36 | AF8: 105 | AG8: 60 | AH8: DB | AI8: DB | AJ8: DB | AK8: K | AL8: =TRUE() -> TRUE | AM8: 56p_kifuto_plecsni.png | AN8: 56s_kifuto_plecsni.png
A9: 10000345 | B9: 10000-345 | C9: ARNO SPHERE MINNOW SALMON 11CM 10PCS/BAG | D9: 24341 | E9: ARNO SPHERE MINNOW | F9: https://energofish.hu/product.php/Mucsali-ARNO-SPHERE-MINNOW/24341/ | G9: 5999018252127 | I9: 95079000 | J9: 210 | K9: Műcsali | L9: 210040 | M9: Gumihal | N9: Arno | O9: 600 | P9: 340 | Q9: 1050 | R9: 570 | S9: =TRUE() -> TRUE | T9: 1 | U9: 1 | V9: 50 | W9: 1.5 | X9: 0.009 | Y9: 45716.411 | Z9: 1 | AA9: <p open="" size:="" style="box-sizing: border-box; margin: 0px 0px 10px; overflow-wrap: break-word; color: rgb(65, 66, 66);"> Ennek a csalinak lágyabb anyaga van és egy igazán érdekes testtel van ellátva, így a nagyobb halakra való horgászathoz is jó alternatíva.</p><p open="" size:="" style="box-sizing: border-box; margin: 0px 0px 10px; overflow-wrap: break-word; color: rgb(65, 66, 66);"> Csukára és süllőre is jó választás! Akár Dropshot módszerhez is.</p> | AD9: 60 | AE9: 34 | AF9: 105 | AG9: 57 | AH9: DB | AI9: DB | AJ9: DB | AK9: K | AL9: =TRUE() -> TRUE | AM9: 56p_kifuto_plecsni.png | AN9: 56s_kifuto_plecsni.png
A10: 10108210 | B10: 10108-210 | C10: ARNO REGULUS ROD 2.1 | D10: 24144 | E10: ARNO REGULUS PERGETŐ BOT | F10: https://energofish.hu/product.php/Botok-ARNO-REGULUS-PERGETO-BOT/24144/ | G10: 5999018245259 | I10: 95071000 | J10: 10 | K10: Botok | L10: 10090 | M10: Pergető | N10: Arno | O10: 2855 | P10: 1790 | Q10: 4990 | R10: 3090 | S10: =TRUE() -> TRUE | T10: 1 | U10: 1 | V10: 50 | W10: 10.15 | X10: 0.0587 | Y10: 45553.314 | Z10: 1 | AA10: <p> Arno Regulus pergető bot</p><p> A megfelelő minőséggel rendelkező, mégis megfizethető árkategóriájú Regulus Spin pergetőbotok a medium pergetés szükségeteihez nyújtanak tökéletes variánst.</p><p> Kényelmes EVAnyél, masszív orsótartó és a fonott zsinóros horgászatnak tökéletesen megfelelő gyűrűsor került a botra.</p><p> A piros-fekete dizájnt kapott Regulus Spin egy könnyű, tökéletesen kiegyensúlyozott, erős-gerinces pergető bot, mely az őszi csukázáshoz is tökéletes választás, függetlenül a használt műcsaliktól.</p><p> Dobósúlyának köszönhetően, a gumihalazástól, a támolygózásig széleskörűen alkalmazható széria.</p> | AI10: DB | AK10: K | AL10: =TRUE() -> TRUE | AM10: 56p_kifuto_plecsni.png | AN10: 56s_kifuto_plecsni.png
